<?xml version="1.0"?>
<sdf version="1.6">
  <world name="default">
    <light name="sun" type="directional">
      <cast_shadows>1</cast_shadows>
      <pose frame="">0 0 10 0 -0 0</pose>
      <diffuse>0.8 0.8 0.8 1</diffuse>
      <specular>0.2 0.2 0.2 1</specular>
      <attenuation>
        <range>1000</range>
        <constant>0.9</constant>
        <linear>0.01</linear>
        <quadratic>0.001</quadratic>
      </attenuation>
      <direction>-0.5 0.1 -0.9</direction>
    </light>
    <model name="ground_plane">
      <static>1</static>
      <link name="link">
        <collision name="collision">
          <geometry>
            <plane>
              <normal>0 0 1</normal>
              <size>100 100</size>
            </plane>
          </geometry>
          <surface>
            <contact>
              <collide_bitmask>65535</collide_bitmask>
              <ode/>
            </contact>
            <friction>
              <ode>
                <mu>100</mu>
                <mu2>50</mu2>
              </ode>
              <torsional>
                <ode/>
              </torsional>
            </friction>
            <bounce/>
          </surface>
          <max_contacts>10</max_contacts>
        </collision>
        <visual name="visual">
          <cast_shadows>0</cast_shadows>
          <geometry>
            <plane>
              <normal>0 0 1</normal>
              <size>100 100</size>
            </plane>
          </geometry>
          <material>
            <script>
              <uri>file://media/materials/scripts/gazebo.material</uri>
              <name>Gazebo/Grey</name>
            </script>
          </material>
        </visual>
        <self_collide>0</self_collide>
        <enable_wind>0</enable_wind>
        <kinematic>0</kinematic>
      </link>
    </model>
    <gravity>0 0 -9.8</gravity>
    <magnetic_field>6e-06 2.3e-05 -4.2e-05</magnetic_field>
    <atmosphere type="adiabatic"/>
    <physics name="default_physics" default="0" type="ode">
      <max_step_size>0.001</max_step_size>
      <real_time_factor>1</real_time_factor>
      <real_time_update_rate>1000</real_time_update_rate>
    </physics>
    <scene>
      <ambient>0.4 0.4 0.4 1</ambient>
      <background>0.7 0.7 0.7 1</background>
      <shadows>1</shadows>
    </scene>
    <wind/>
    <spherical_coordinates>
      <surface_model>EARTH_WGS84</surface_model>
      <latitude_deg>0</latitude_deg>
      <longitude_deg>0</longitude_deg>
      <elevation>0</elevation>
      <heading_deg>0</heading_deg>
    </spherical_coordinates>
    <state world_name="default">
      <sim_time>37 931000000</sim_time>
      <real_time>38 94054642</real_time>
      <wall_time>1542632630 819302195</wall_time>
      <iterations>37931</iterations>
      <model name="ground_plane">
        <pose frame="">0 0 0 0 -0 0</pose>
        <scale>1 1 1</scale>
        <link name="link">
          <pose frame="">0 0 0 0 -0 0</pose>
          <velocity>0 0 0 0 -0 0</velocity>
          <acceleration>0 0 0 0 -0 0</acceleration>
          <wrench>0 0 0 0 -0 0</wrench>
        </link>
      </model>
      <light name="sun">
        <pose frame="">0 0 10 0 -0 0</pose>
      </light>
    </state>
    <gui fullscreen="0">
      <camera name="user_camera">
        <pose frame="">5 -5 2 0 0.275643 2.35619</pose>
        <view_controller>orbit</view_controller>
        <projection_type>perspective</projection_type>
      </camera>
    </gui>
            <model name="Gazebo_2019">
                    <static>true</static>
                    <link name="Bodenplattedummyv47_1">
                            <pose>0.0 0.0 0.0 1.5707963267948966 -0.0 0.0</pose>
                            <inertial>
                                    <pose>0.10889846412291833 0.0004772385251447973 -0.021993038407167105 0 0 0</pose>
                                    <mass>0.27286904120108824</mass>
                                    <inertia>
                                            <ixx>0.0008131320677199672</ixx>
                                            <ixy>-1.3101061244852367e-05</ixy>
                                            <ixz>2.8624938490559513e-06</ixz>
                                            <iyy>0.005660773886645985</iyy>
                                            <iyz>0.0006535209046744606</iyz>
                                            <izz>0.0062092100373661386</izz>
                                    </inertia>
                            </inertial>
                            <collision name="Bodenplattedummyv47_1_collision">
                                    <geometry>
                                            <mesh>
                                                    <uri>model://meshes/Bodenplattedummyv47.stl</uri>
                                                    <scale>0.001 0.001 0.001</scale>
                                            </mesh>
                                    </geometry>
                            </collision>
                            <visual name="Bodenplattedummyv47_1_visual">
                                    <geometry>
                                            <mesh>
                                                    <uri>model://meshes/Bodenplattedummyv47.stl</uri>
                                                    <scale>0.001 0.001 0.001</scale>
                                            </mesh>
                                    </geometry>
                            </visual>
                    </link>
                    <link name="Turnigy4206Statorv1_1">
                            <pose>1.2106737053846345e-15 0.004999999999999994 -0.08785151957527598 -8.636650667801967e-15 -8.674803281807767e-15 0.783194272704847</pose>
                            <inertial>
                                    <pose>-5.345208010143084e-07 0.009238002577085522 -1.3656168635634014e-07 0 0 0</pose>
                                    <mass>0.010150401823259367</mass>
                                    <inertia>
                                            <ixx>6.377820108487859e-05</ixx>
                                            <ixy>-4.1971232837996204e-10</ixy>
                                            <ixz>-3.9899009605991435e-06</ixz>
                                            <iyy>1.5718976341437403e-06</iyy>
                                            <iyz>6.371056118226193e-13</iyz>
                                            <izz>6.352392103072553e-05</izz>
                                    </inertia>
                            </inertial>
                            <collision name="Turnigy4206Statorv1_1_collision">
                                    <geometry>
                                            <mesh>
                                                    <uri>model://meshes/Turnigy4206Statorv1.stl</uri>
                                                    <scale>0.001 0.001 0.001</scale>
                                            </mesh>
                                    </geometry>
                            </collision>
                            <visual name="Turnigy4206Statorv1_1_visual">
                                    <geometry>
                                            <mesh>
                                                    <uri>model://meshes/Turnigy4206Statorv1.stl</uri>
                                                    <scale>0.001 0.001 0.001</scale>
                                            </mesh>
                                    </geometry>
                            </visual>
                    </link>
                    <link name="Reifen46mmcutv4_1">
                            <pose>0.0 0.0 0.0 1.5707963267948966 -0.0 0.0</pose>
                            <inertial>
                                    <pose>-1.042102168689448e-14 -0.08726751260918761 -0.004999999999845468 0 0 0</pose>
                                    <mass>0.04365928629152999</mass>
                                    <inertia>
                                            <ixx>0.00035342525833232833</ixx>
                                            <ixy>-3.9323282408076884e-17</ixy>
                                            <ixz>-1.90501865846779e-05</ixz>
                                            <iyy>3.595843848338361e-05</iyy>
                                            <iyz>-4.904471439033387e-13</iyz>
                                            <izz>0.0003523337761705924</izz>
                                    </inertia>
                            </inertial>
                            <collision name="Reifen46mmcutv4_1_collision">
                                    <geometry>
                                            <mesh>
                                                    <uri>model://meshes/Reifen46mmcutv4.stl</uri>
                                                    <scale>0.001 0.001 0.001</scale>
                                            </mesh>
                                    </geometry>
                            </collision>
                            <visual name="Reifen46mmcutv4_1_visual">
                                    <geometry>
                                            <mesh>
                                                    <uri>model://meshes/Reifen46mmcutv4.stl</uri>
                                                    <scale>0.001 0.001 0.001</scale>
                                            </mesh>
                                    </geometry>
                            </visual>
                    </link>
                    <joint name="Umdrehung3" type="revolute">
                            <parent>Turnigy4206Statorv1_1</parent>
                            <child>Reifen46mmcutv4_1</child>
                            <pose>0 0 0.0 0 0 0</pose>
                            <axis>
                                    <xyz>0 1 0</xyz>
                                    <use_parent_model_frame>0</use_parent_model_frame>
                            </axis>
                    </joint>

                    <joint name="BaseToStator" type="revolute">
                            <parent>Bodenplattedummyv47_1</parent>
                            <child>Turnigy4206Statorv1_1</child>
                            <pose>0 0.0 0.045 0 0 0</pose>
                            <axis>
                                    <xyz>0 0 1</xyz>
                                    <use_parent_model_frame>0</use_parent_model_frame>
                            </axis>
                    </joint>
            </model>
  </world>
</sdf>
